Workbook

Sheet Senin
A1: ="Pengiriman ( Senin ) Tgl. "&TEXT(DATE(2018,7,23),"dd mmmm yyyy") -> Pengiriman ( Senin ) Tgl. 23 July 2018
A3: STO Number | B3: Supplier | C3: Item | D3: Qty | E3: UoM | F3: Promise Date | H3: Ship To | J3: From | K3: Seq | L3: VehicleType | M3: Keterangan | N3: Brand
A4: 4701365886 | B4: HM Sampoerna PT | C4: FA045796.14 | D4: 729 | E4: Box | F4: 43304 | G4: ZD1L | H4: Depo Medan | I4: ZD4B | J4: DC Karawang Lot. 41 | K4: 1 | L4: Cont 40FT HC | N4: DSM12RC156L8
A5: 4701365887 | B5: HM Sampoerna PT | C5: FA044121.19 | D5: 1138 | E5: Box | F5: 43304 | G5: ZD1L | H5: Depo Medan | I5: ZD4B | J5: DC Karawang Lot. 41 | K5: 2 | L5: Cont 40FT HC | N5: MLD16RC204L8
A6: 4701365888 | B6: HM Sampoerna PT | C6: FA044121.19 | D6: 1138 | E6: Box | F6: 43304 | G6: ZD1L | H6: Depo Medan | I6: ZD4B | J6: DC Karawang Lot. 41 | K6: 3 | L6: Cont 40FT HC | N6: MLD16RC204L8
A7: 4701365889 | B7: HM Sampoerna PT | C7: FA044121.19 | D7: 1138 | E7: Box | F7: 43304 | G7: ZD1L | H7: Depo Medan | I7: ZD4B | J7: DC Karawang Lot. 41 | K7: 4 | L7: Cont 40FT HC | N7: MLD16RC204L8
A8: 4701365890 | B8: HM Sampoerna PT | C8: FA044121.19 | D8: 1138 | E8: Box | F8: 43304 | G8: ZD1L | H8: Depo Medan | I8: ZD4B | J8: DC Karawang Lot. 41 | K8: 5 | L8: Cont 40FT HC | N8: MLD16RC204L8
A9: 4701365891 | B9: HM Sampoerna PT | C9: FA035621.15 | D9: 95 | E9: Box | F9: 43304 | G9: ZD1K | H9: DPC Sibolga | I9: ZD4A | J9: DC Karawang Lot. 17 | K9: 6 | L9: Cont 20FT | N9: DSB12RA170L8
B10: HM Sampoerna PT | C10: FA064382.01 | D10: 140 | E10: Box | F10: 43304 | G10: ZD1K | H10: DPC Sibolga | I10: ZD4A | J10: DC Karawang Lot. 17 | K10: 6 | L10: Cont 20FT | N10: DSS12RA151L8
B11: HM Sampoerna PT | C11: FA010784.17 | D11: 4 | E11: Box | F11: 43304 | G11: ZD1K | H11: DPC Sibolga | I11: ZD4A | J11: DC Karawang Lot. 17 | K11: 6 | L11: Cont 20FT | N11: DSS16RA202L8
B12: HM Sampoerna PT | C12: FA071115.00 | D12: 80 | E12: Box | F12: 43304 | G12: ZD1K | H12: DPC Sibolga | I12: ZD4A | J12: DC Karawang Lot. 17 | K12: 6 | L12: Cont 20FT | N12: PNK12RC112L8
A13: 4701365892 | B13: HM Sampoerna PT | C13: FA071115.00 | D13: 61 | E13: Box | F13: 43304 | G13: ZD1K | H13: DPC Sibolga | I13: ZD4A | J13: DC Karawang Lot. 17 | K13: 7 | L13: Cont 20FT | N13: PNK12RC112L8
A14: 4701365893 | B14: Philip Morris Indonesia PT | C14: FA052576.13 | D14: 80 | E14: Box | F14: 43304 | G14: ZD1K | H14: DPC Sibolga | I14: ZD4A | J14: DC Karawang Lot. 17 | K14: 7 | L14: Cont 20FT | N14: MBR20RC233L8
B15: Philip Morris Indonesia PT | C15: FA068715.04 | D15: 10 | E15: Box | F15: 43304 | G15: ZD1K | H15: DPC Sibolga | I15: ZD4A | J15: DC Karawang Lot. 17 | K15: 7 | L15: Cont 20FT | N15: MBL20RB233L8
A16: 4701365894 | B16: HM Sampoerna PT | C16: FA044121.19 | D16: 270 | E16: Box | F16: 43304 | G16: ZD1K | H16: DPC Sibolga | I16: ZD4B | J16: DC Karawang Lot. 41 | K16: 7 | L16: Cont 20FT | N16: MLD16RC204L8
A17: 4701365895 | B17: HM Sampoerna PT | C17: FA045796.14 | D17: 4 | E17: Box | F17: 43304 | G17: ZD1K | H17: DPC Sibolga | I17: ZD4B | J17: DC Karawang Lot. 41 | K17: 8 | L17: Cont 20FT | N17: DSM12RC156L8
B18: HM Sampoerna PT | C18: FA045795.13 | D18: 110 | E18: Box | F18: 43304 | G18: ZD1K | H18: DPC Sibolga | I18: ZD4B | J18: DC Karawang Lot. 41 | K18: 8 | L18: Cont 20FT | N18: MLD12RB146L8
B19: HM Sampoerna PT | C19: FA044121.19 | D19: =190-7 -> 183 | E19: Box | F19: 43304 | G19: ZD1K | H19: DPC Sibolga | I19: ZD4B | J19: DC Karawang Lot. 41 | K19: 8 | L19: Cont 20FT | N19: MLD16RC204L8
B20: HM Sampoerna PT | C20: FA061184.02 | D20: =13+5 -> 18 | E20: Box | F20: 43304 | G20: ZD1K | H20: DPC Sibolga | I20: ZD4B | J20: DC Karawang Lot. 41 | K20: 8 | L20: Cont 20FT | N20: MFB20RA224L8
B21: HM Sampoerna PT | C21: FA045300.04 | D21: 148 | E21: Box | F21: 43304 | G21: ZD1K | H21: DPC Sibolga | I21: ZD4B | J21: DC Karawang Lot. 41 | K21: 8 | L21: Cont 20FT | N21: DMM16RA179L8
A22: 4701365896 | B22: HM Sampoerna PT | C22: FA048259.05 | D22: 60 | E22: Box | F22: 43304 | G22: ZD1K | H22: DPC Sibolga | I22: ZD4B | J22: DC Karawang Lot. 41 | K22: 9 | L22: Cont 20FT | N22: AVR20RB226L8
B23: HM Sampoerna PT | C23: FA044121.19 | D23: =416+7 -> 423 | E23: Box | F23: 43304 | G23: ZD1K | H23: DPC Sibolga | I23: ZD4B | J23: DC Karawang Lot. 41 | K23: 9 | L23: Cont 20FT | N23: MLD16RC204L8
B24: HM Sampoerna PT | C24: FA061184.02 | D24: =5-5 -> 0 | E24: Box | F24: 43304 | G24: ZD1K | H24: DPC Sibolga | I24: ZD4B | J24: DC Karawang Lot. 41 | K24: 9 | L24: Cont 20FT | N24: MFB20RA224L8
A25: 4701365897 | B25: HM Sampoerna PT | C25: FA048259.05 | D25: 17 | E25: Box | F25: 43304 | G25: ZD2A | H25: ADW Padang | I25: ZD4A | J25: DC Karawang Lot. 17 | K25: 10 | L25: Cont 40FT HC | N25: AVR20RB226L8
B26: HM Sampoerna PT | C26: FA048258.06 | D26: 12 | E26: Box | F26: 43304 | G26: ZD2A | H26: ADW Padang | I26: ZD4A | J26: DC Karawang Lot. 17 | K26: 10 | L26: Cont 40FT HC | N26: AVM20RB226L8
B27: HM Sampoerna PT | C27: FA035621.15 | D27: 100 | E27: Box | F27: 43304 | G27: ZD2A | H27: ADW Padang | I27: ZD4A | J27: DC Karawang Lot. 17 | K27: 10 | L27: Cont 40FT HC | N27: DSB12RA170L8
B28: HM Sampoerna PT | C28: FA064382.01 | D28: 100 | E28: Box | F28: 43304 | G28: ZD2A | H28: ADW Padang | I28: ZD4A | J28: DC Karawang Lot. 17 | K28: 10 | L28: Cont 40FT HC | N28: DSS12RA151L8
B29: HM Sampoerna PT | C29: FA010784.17 | D29: 12 | E29: Box | F29: 43304 | G29: ZD2A | H29: ADW Padang | I29: ZD4A | J29: DC Karawang Lot. 17 | K29: 10 | L29: Cont 40FT HC | N29: DSS16RA202L8
B30: HM Sampoerna PT | C30: FA071127.00 | D30: 50 | E30: Box | F30: 43304 | G30: ZD2A | H30: ADW Padang | I30: ZD4A | J30: DC Karawang Lot. 17 | K30: 10 | L30: Cont 40FT HC | N30: SAH12RC113L8
B31: HM Sampoerna PT | C31: FA070776.00 | D31: 320 | E31: Box | F31: 43304 | G31: ZD2A | H31: ADW Padang | I31: ZD4A | J31: DC Karawang Lot. 17 | K31: 10 | L31: Cont 40FT HC | N31: UBL12SA134L8
A32: 4701365898 | B32: Philip Morris Indonesia PT | C32: FA068715.04 | D32: 150 | E32: Box | F32: 43304 | G32: ZD2A | H32: ADW Padang | I32: ZD4A | J32: DC Karawang Lot. 17 | K32: 10 | L32: Cont 40FT HC | N32: MBL20RB233L8
B33: Philip Morris Indonesia PT | C33: FA069748.02 | D33: 13 | E33: Box | F33: 43304 | G33: ZD2A | H33: ADW Padang | I33: ZD4A | J33: DC Karawang Lot. 17 | K33: 10 | L33: Cont 40FT HC | N33: MMI20RC233L8
A34: 4701365899 | B34: HM Sampoerna PT | C34: FA035621.15 | D34: 30 | E34: Box | F34: 43304 | G34: ZD2E | H34: ADW Duri | I34: ZD4A | J34: DC Karawang Lot. 17 | K34: 11 | L34: CBU | N34: DSB12RA170L8
B35: HM Sampoerna PT | C35: FA010784.17 | D35: 20 | E35: Box | F35: 43304 | G35: ZD2E | H35: ADW Duri | I35: ZD4A | J35: DC Karawang Lot. 17 | K35: 11 | L35: CBU | N35: DSS16RA202L8
B36: HM Sampoerna PT | C36: FA071127.00 | D36: 23 | E36: Box | F36: 43304 | G36: ZD2E | H36: ADW Duri | I36: ZD4A | J36: DC Karawang Lot. 17 | K36: 11 | L36: CBU | N36: SAH12RC113L8
A37: 4701365900 | B37: Philip Morris Indonesia PT | C37: FA068715.04 | D37: 34 | E37: Box | F37: 43304 | G37: ZD2E | H37: ADW Duri | I37: ZD4A | J37: DC Karawang Lot. 17 | K37: 11 | L37: CBU | N37: MBL20RB233L8
B38: Philip Morris Indonesia PT | C38: FA069748.02 | D38: 4 | E38: Box | F38: 43304 | G38: ZD2E | H38: ADW Duri | I38: ZD4A | J38: DC Karawang Lot. 17 | K38: 11 | L38: CBU | N38: MMI20RC233L8
A39: 4701365901 | B39: HM Sampoerna PT | C39: FA048259.05 | D39: 18 | E39: Box | F39: 43304 | G39: ZD2E | H39: ADW Duri | I39: ZD4B | J39: DC Karawang Lot. 41 | K39: 11 | L39: CBU | N39: AVR20RB226L8
B40: HM Sampoerna PT | C40: FA045795.13 | D40: 72 | E40: Box | F40: 43304 | G40: ZD2E | H40: ADW Duri | I40: ZD4B | J40: DC Karawang Lot. 41 | K40: 11 | L40: CBU | N40: MLD12RB146L8
B41: HM Sampoerna PT | C41: FA044121.19 | D41: 300 | E41: Box | F41: 43304 | G41: ZD2E | H41: ADW Duri | I41: ZD4B | J41: DC Karawang Lot. 41 | K41: 11 | L41: CBU | N41: MLD16RC204L8
...

Sheet Selasa
A1: ="Pengiriman ( Selasa ) Tgl. "&TEXT(MID(Senin!A1,FIND(".",Senin!A1,1)+2,17)+1,"dd mmmm yyyy") -> Pengiriman ( Selasa ) Tgl. 24 July 2018
A3: STO Number | B3: Supplier | C3: Item | D3: Qty | E3: UoM | F3: Promise Date | H3: Ship To | J3: From | K3: Seq | L3: VehicleType | M3: Keterangan | N3: Brand
A4: 4701366876 | B4: HM Sampoerna PT | C4: FA044121.19 | D4: 1138 | E4: Box | F4: 43305 | G4: ZD1L | H4: Depo Medan | I4: ZD4B | J4: DC Karawang Lot. 41 | K4: 1 | L4: Cont 40FT HC | N4: MLD16RC204L8
A5: 4701366877 | B5: HM Sampoerna PT | C5: FA048259.05 | D5: 79 | E5: Box | F5: 43305 | G5: ZD1L | H5: Depo Medan | I5: ZD4B | J5: DC Karawang Lot. 41 | K5: 2 | L5: Cont 40FT HC | N5: AVR20RB226L8
B6: HM Sampoerna PT | C6: FA045796.14 | D6: 670 | E6: Box | F6: 43305 | G6: ZD1L | H6: Depo Medan | I6: ZD4B | J6: DC Karawang Lot. 41 | K6: 2 | L6: Cont 40FT HC | N6: DSM12RC156L8
A7: 4701366878 | B7: HM Sampoerna PT | C7: FA064382.01 | D7: 139 | E7: Box | F7: 43305 | G7: ZD1K | H7: DPC Sibolga | I7: ZD4A | J7: DC Karawang Lot. 17 | K7: 3 | L7: Cont 20FT | N7: DSS12RA151L8
B8: PT. Sampoerna Indonesia Sembilan | C8: FA068324.02 | D8: 23 | E8: Box | F8: 43305 | G8: ZD1K | H8: DPC Sibolga | I8: ZD4A | J8: DC Karawang Lot. 17 | K8: 3 | L8: Cont 20FT | N8: UML12RB134L8
B9: HM Sampoerna PT | C9: FA071115.00 | D9: 30 | E9: Box | F9: 43305 | G9: ZD1K | H9: DPC Sibolga | I9: ZD4A | J9: DC Karawang Lot. 17 | K9: 3 | L9: Cont 20FT | N9: PNK12RC112L8
B10: PT. Sampoerna Indonesia Sembilan | C10: FA067814.02 | D10: 50 | E10: Box | F10: 43305 | G10: ZD1K | H10: DPC Sibolga | I10: ZD4A | J10: DC Karawang Lot. 17 | K10: 3 | L10: Cont 20FT | N10: UML16RB179L8
A11: 4701366879 | B11: Philip Morris Indonesia PT | C11: FA052576.13 | D11: 85 | E11: Box | F11: 43305 | G11: ZD1K | H11: DPC Sibolga | I11: ZD4A | J11: DC Karawang Lot. 17 | K11: 3 | L11: Cont 20FT | N11: MBR20RC233L8
B12: Philip Morris Indonesia PT | C12: FA068715.04 | D12: 12 | E12: Box | F12: 43305 | G12: ZD1K | H12: DPC Sibolga | I12: ZD4A | J12: DC Karawang Lot. 17 | K12: 3 | L12: Cont 20FT | N12: MBL20RB233L8
A13: 4701366880 | B13: PT. Sampoerna Indonesia Sembilan | C13: FA067814.02 | D13: 190 | E13: Box | F13: 43305 | G13: ZD2A | H13: ADW Padang | I13: ZD4A | J13: DC Karawang Lot. 17 | K13: 4 | L13: Cont 40FT HC | N13: UML16RB179L8
A14: 4701366881 | B14: Philip Morris Indonesia PT | C14: FA052576.13 | D14: 150 | E14: Box | F14: 43305 | G14: ZD2A | H14: ADW Padang | I14: ZD4A | J14: DC Karawang Lot. 17 | K14: 4 | L14: Cont 40FT HC | N14: MBR20RC233L8
A15: 4701366882 | B15: HM Sampoerna PT | C15: FA048259.05 | D15: 41 | E15: Box | F15: 43305 | G15: ZD2A | H15: ADW Padang | I15: ZD4B | J15: DC Karawang Lot. 41 | K15: 4 | L15: Cont 40FT HC | N15: AVR20RB226L8
B16: HM Sampoerna PT | C16: FA044121.19 | D16: 440 | E16: Box | F16: 43305 | G16: ZD2A | H16: ADW Padang | I16: ZD4B | J16: DC Karawang Lot. 41 | K16: 4 | L16: Cont 40FT HC | N16: MLD16RC204L8
B17: HM Sampoerna PT | C17: FA067816.01 | D17: 162 | E17: Box | F17: 43305 | G17: ZD2A | H17: ADW Padang | I17: ZD4B | J17: DC Karawang Lot. 41 | K17: 4 | L17: Cont 40FT HC | N17: UBL12RA134L8
A18: 4701366883 | B18: HM Sampoerna PT | C18: FA044121.19 | D18: 898 | E18: Box | F18: 43305 | G18: ZD2A | H18: ADW Padang | I18: ZD4B | J18: DC Karawang Lot. 41 | K18: 5 | L18: Cont 40FT HC | N18: MLD16RC204L8
B19: HM Sampoerna PT | C19: FA045300.04 | D19: 240 | E19: Box | F19: 43305 | G19: ZD2A | H19: ADW Padang | I19: ZD4B | J19: DC Karawang Lot. 41 | K19: 5 | L19: Cont 40FT HC | N19: DMM16RA179L8
A20: 4701366884 | B20: HM Sampoerna PT | C20: FA045796.14 | D20: 83 | E20: Box | F20: 43305 | G20: ZD2A | H20: ADW Padang | I20: ZD4B | J20: DC Karawang Lot. 41 | K20: 6 | L20: Cont 40FT HC | N20: DSM12RC156L8
B21: HM Sampoerna PT | C21: FA045795.13 | D21: 240 | E21: Box | F21: 43305 | G21: ZD2A | H21: ADW Padang | I21: ZD4B | J21: DC Karawang Lot. 41 | K21: 6 | L21: Cont 40FT HC | N21: MLD12RB146L8
B22: HM Sampoerna PT | C22: FA044121.19 | D22: =600-8 -> 592 | E22: Box | F22: 43305 | G22: ZD2A | H22: ADW Padang | I22: ZD4B | J22: DC Karawang Lot. 41 | K22: 6 | L22: Cont 40FT HC | N22: MLD16RC204L8
B23: HM Sampoerna PT | C23: FA062333.03 | D23: 10 | E23: Box | F23: 43305 | G23: ZD2A | H23: ADW Padang | I23: ZD4B | J23: DC Karawang Lot. 41 | K23: 6 | L23: Cont 40FT HC | N23: MTB16RA200L8
B24: HM Sampoerna PT | C24: FA045300.04 | D24: 120 | E24: Box | F24: 43305 | G24: ZD2A | H24: ADW Padang | I24: ZD4B | J24: DC Karawang Lot. 41 | K24: 6 | L24: Cont 40FT HC | N24: DMM16RA179L8
A25: 4701366885 | B25: HM Sampoerna PT | C25: FA045795.13 | D25: 330 | E25: Box | F25: 43305 | G25: ZD2A | H25: ADW Padang | I25: ZD4B | J25: DC Karawang Lot. 41 | K25: 7 | L25: Cont 40FT HC | N25: MLD12RB146L8
B26: HM Sampoerna PT | C26: FA044121.19 | D26: 760 | E26: Box | F26: 43305 | G26: ZD2A | H26: ADW Padang | I26: ZD4B | J26: DC Karawang Lot. 41 | K26: 7 | L26: Cont 40FT HC | N26: MLD16RC204L8
A27: 4701366886 | B27: HM Sampoerna PT | C27: FA035621.15 | D27: 90 | E27: Box | F27: 43305 | G27: ZD2D | H27: ADW Pekanbaru | I27: ZD4A | J27: DC Karawang Lot. 17 | K27: 8 | L27: Cont 40FT HC | N27: DSB12RA170L8
B28: HM Sampoerna PT | C28: FA064382.01 | D28: 90 | E28: Box | F28: 43305 | G28: ZD2D | H28: ADW Pekanbaru | I28: ZD4A | J28: DC Karawang Lot. 17 | K28: 8 | L28: Cont 40FT HC | N28: DSS12RA151L8
B29: HM Sampoerna PT | C29: FA010784.17 | D29: 22 | E29: Box | F29: 43305 | G29: ZD2D | H29: ADW Pekanbaru | I29: ZD4A | J29: DC Karawang Lot. 17 | K29: 8 | L29: Cont 40FT HC | N29: DSS16RA202L8
B30: PT. Sampoerna Indonesia Sembilan | C30: FA068324.02 | D30: 100 | E30: Box | F30: 43305 | G30: ZD2D | H30: ADW Pekanbaru | I30: ZD4A | J30: DC Karawang Lot. 17 | K30: 8 | L30: Cont 40FT HC | N30: UML12RB134L8
B31: PT. Sampoerna Indonesia Sembilan | C31: FA067814.02 | D31: 200 | E31: Box | F31: 43305 | G31: ZD2D | H31: ADW Pekanbaru | I31: ZD4A | J31: DC Karawang Lot. 17 | K31: 8 | L31: Cont 40FT HC | N31: UML16RB179L8
B32: HM Sampoerna PT | C32: FA071127.00 | D32: 100 | E32: Box | F32: 43305 | G32: ZD2D | H32: ADW Pekanbaru | I32: ZD4A | J32: DC Karawang Lot. 17 | K32: 8 | L32: Cont 40FT HC | N32: SAH12RC113L8
A33: 4701366887 | B33: Philip Morris Indonesia PT | C33: FA052576.13 | D33: 150 | E33: Box | F33: 43305 | G33: ZD2D | H33: ADW Pekanbaru | I33: ZD4A | J33: DC Karawang Lot. 17 | K33: 8 | L33: Cont 40FT HC | N33: MBR20RC233L8
B34: Philip Morris Indonesia PT | C34: FA068715.04 | D34: 100 | E34: Box | F34: 43305 | G34: ZD2D | H34: ADW Pekanbaru | I34: ZD4A | J34: DC Karawang Lot. 17 | K34: 8 | L34: Cont 40FT HC | N34: MBL20RB233L8
B35: Philip Morris Indonesia PT | C35: FA069748.02 | D35: 50 | E35: Box | F35: 43305 | G35: ZD2D | H35: ADW Pekanbaru | I35: ZD4A | J35: DC Karawang Lot. 17 | K35: 8 | L35: Cont 40FT HC | N35: MMI20RC233L8
A36: 4701366888 | B36: HM Sampoerna PT | C36: FA048259.05 | D36: 25 | E36: Box | F36: 43305 | G36: ZD2D | H36: ADW Pekanbaru | I36: ZD4B | J36: DC Karawang Lot. 41 | K36: 9 | L36: Cont 40FT HC | N36: AVR20RB226L8
B37: HM Sampoerna PT | C37: FA044121.19 | D37: 660 | E37: Box | F37: 43305 | G37: ZD2D | H37: ADW Pekanbaru | I37: ZD4B | J37: DC Karawang Lot. 41 | K37: 9 | L37: Cont 40FT HC | N37: MLD16RC204L8
B38: HM Sampoerna PT | C38: FA067816.01 | D38: 82 | E38: Box | F38: 43305 | G38: ZD2D | H38: ADW Pekanbaru | I38: ZD4B | J38: DC Karawang Lot. 41 | K38: 9 | L38: Cont 40FT HC | N38: UBL12RA134L8
B39: HM Sampoerna PT | C39: FA045300.04 | D39: 240 | E39: Box | F39: 43305 | G39: ZD2D | H39: ADW Pekanbaru | I39: ZD4B | J39: DC Karawang Lot. 41 | K39: 9 | L39: Cont 40FT HC | N39: DMM16RA179L8
A40: 4701366889 | B40: HM Sampoerna PT | C40: FA044121.19 | D40: 775 | E40: Box | F40: 43305 | G40: ZD3D | H40: ADW Palembang | I40: ZD4B | J40: DC Karawang Lot. 41 | K40: 10 | L40: CBU | N40: MLD16RC204L8
A41: 4701366890 | B41: HM Sampoerna PT | C41: FA045796.14 | D41: 10 | E41: Box | F41: 43305 | G41: ZD3E | H41: ADW Lahat | I41: ZD4A | J41: DC Karawang Lot. 17 | K41: 11 | L41: CBU | M41: *Gab Lahat + Baturaja | N41: DSM12RC156L8
...

Sheet Rabu
A1: ="Pengiriman ( Rabu ) Tgl. "&TEXT(MID(Selasa!A1,FIND(".",Selasa!A1,1)+2,17)+1,"dd mmmm yyyy") -> Pengiriman ( Rabu ) Tgl. 25 July 2018
A3: STO Number | B3: Supplier | C3: Item | D3: Qty | E3: UoM | F3: Promise Date | H3: Ship To | J3: From | K3: Seq | L3: VehicleType | M3: Keterangan | N3: Brand
A4: 4701367438 | B4: HM Sampoerna PT | C4: FA035621.15 | D4: 400 | E4: Box | F4: 43306 | G4: ZD1L | H4: Depo Medan | I4: ZD4A | J4: DC Karawang Lot. 17 | K4: 1 | L4: Cont 40FT HC | N4: DSB12RA170L8
A5: 4701367439 | B5: Philip Morris Indonesia PT | C5: FA052576.13 | D5: 150 | E5: Box | F5: 43306 | G5: ZD1L | H5: Depo Medan | I5: ZD4A | J5: DC Karawang Lot. 17 | K5: 1 | L5: Cont 40FT HC | N5: MBR20RC233L8
A6: 4701367440 | B6: HM Sampoerna PT | C6: FA044121.19 | D6: 570 | E6: Box | F6: 43306 | G6: ZD1L | H6: Depo Medan | I6: ZD4B | J6: DC Karawang Lot. 41 | K6: 1 | L6: Cont 40FT HC | N6: MLD16RC204L8
A7: 4701367441 | B7: HM Sampoerna PT | C7: FA044121.19 | D7: 1138 | E7: Box | F7: 43306 | G7: ZD1L | H7: Depo Medan | I7: ZD4B | J7: DC Karawang Lot. 41 | K7: 2 | L7: Cont 40FT HC | N7: MLD16RC204L8
A8: 4701367442 | B8: HM Sampoerna PT | C8: FA045796.14 | D8: 729 | E8: Box | F8: 43306 | G8: ZD1L | H8: Depo Medan | I8: ZD4B | J8: DC Karawang Lot. 41 | K8: 3 | L8: Cont 40FT HC | N8: DSM12RC156L8
A9: 4701367443 | B9: HM Sampoerna PT | C9: FA044121.19 | D9: 1138 | E9: Box | F9: 43306 | G9: ZD1L | H9: Depo Medan | I9: ZD4B | J9: DC Karawang Lot. 41 | K9: 4 | L9: Cont 40FT HC | N9: MLD16RC204L8
A10: 4701367444 | B10: HM Sampoerna PT | C10: FA035621.15 | D10: 270 | E10: Box | F10: 43306 | G10: ZD1L | H10: Depo Medan | I10: ZD4A | J10: DC Karawang Lot. 17 | K10: 5 | L10: Cont 40FT HC | N10: DSB12RA170L8
B11: HM Sampoerna PT | C11: FA071115.00 | D11: 500 | E11: Box | F11: 43306 | G11: ZD1L | H11: Depo Medan | I11: ZD4A | J11: DC Karawang Lot. 17 | K11: 5 | L11: Cont 40FT HC | N11: PNK12RC112L8
A12: 4701367445 | B12: HM Sampoerna PT | C12: FA035621.15 | D12: 70 | E12: Box | F12: 43306 | G12: ZD2A | H12: ADW Padang | I12: ZD4A | J12: DC Karawang Lot. 17 | K12: 6 | L12: Cont 40FT HC | N12: DSB12RA170L8
B13: HM Sampoerna PT | C13: FA064382.01 | D13: 210 | E13: Box | F13: 43306 | G13: ZD2A | H13: ADW Padang | I13: ZD4A | J13: DC Karawang Lot. 17 | K13: 6 | L13: Cont 40FT HC | N13: DSS12RA151L8
B14: HM Sampoerna PT | C14: FA044121.19 | D14: 120 | E14: Box | F14: 43306 | G14: ZD2A | H14: ADW Padang | I14: ZD4A | J14: DC Karawang Lot. 17 | K14: 6 | L14: Cont 40FT HC | N14: MLD16RC204L8
B15: PT. Sampoerna Indonesia Sembilan | C15: FA068324.02 | D15: 117 | E15: Box | F15: 43306 | G15: ZD2A | H15: ADW Padang | I15: ZD4A | J15: DC Karawang Lot. 17 | K15: 6 | L15: Cont 40FT HC | N15: UML12RB134L8
B16: PT. Sampoerna Indonesia Sembilan | C16: FA067814.02 | D16: 210 | E16: Box | F16: 43306 | G16: ZD2A | H16: ADW Padang | I16: ZD4A | J16: DC Karawang Lot. 17 | K16: 6 | L16: Cont 40FT HC | N16: UML16RB179L8
A17: 4701367446 | B17: Philip Morris Indonesia PT | C17: FA052576.13 | D17: 80 | E17: Box | F17: 43306 | G17: ZD2A | H17: ADW Padang | I17: ZD4A | J17: DC Karawang Lot. 17 | K17: 6 | L17: Cont 40FT HC | N17: MBR20RC233L8
B18: Philip Morris Indonesia PT | C18: FA068715.04 | D18: 137 | E18: Box | F18: 43306 | G18: ZD2A | H18: ADW Padang | I18: ZD4A | J18: DC Karawang Lot. 17 | K18: 6 | L18: Cont 40FT HC | N18: MBL20RB233L8
A19: 4701367447 | B19: HM Sampoerna PT | C19: FA045795.13 | D19: 270 | E19: Box | F19: 43306 | G19: ZD2A | H19: ADW Padang | I19: ZD4B | J19: DC Karawang Lot. 41 | K19: 7 | L19: Cont 40FT HC | N19: MLD12RB146L8
B20: HM Sampoerna PT | C20: FA044121.19 | D20: 819 | E20: Box | F20: 43306 | G20: ZD2A | H20: ADW Padang | I20: ZD4B | J20: DC Karawang Lot. 41 | K20: 7 | L20: Cont 40FT HC | N20: MLD16RC204L8
A21: 4701367448 | B21: HM Sampoerna PT | C21: FA035621.15 | D21: 100 | E21: Box | F21: 43306 | G21: ZD2A | H21: ADW Padang | I21: ZD4A | J21: DC Karawang Lot. 17 | K21: 8 | L21: CBU | N21: DSB12RA170L8
B22: PT. Sampoerna Indonesia Sembilan | C22: FA068324.02 | D22: 83 | E22: Box | F22: 43306 | G22: ZD2A | H22: ADW Padang | I22: ZD4A | J22: DC Karawang Lot. 17 | K22: 8 | L22: CBU | N22: UML12RB134L8
B23: HM Sampoerna PT | C23: FA070776.00 | D23: 232 | E23: Box | F23: 43306 | G23: ZD2A | H23: ADW Padang | I23: ZD4A | J23: DC Karawang Lot. 17 | K23: 8 | L23: CBU | N23: UBL12SA134L8
A24: 4701367449 | B24: HM Sampoerna PT | C24: FA062333.03 | D24: 1 | E24: Box | F24: 43306 | G24: ZD2A | H24: ADW Padang | I24: ZD4B | J24: DC Karawang Lot. 41 | K24: 8 | L24: CBU | N24: MTB16RA200L8
B25: HM Sampoerna PT | C25: FA061184.02 | D25: 185 | E25: Box | F25: 43306 | G25: ZD2A | H25: ADW Padang | I25: ZD4B | J25: DC Karawang Lot. 41 | K25: 8 | L25: CBU | N25: MFB20RA224L8
A26: 4701367450 | B26: HM Sampoerna PT | C26: FA048259.05 | D26: 30 | E26: Box | F26: 43306 | G26: ZD2D | H26: ADW Pekanbaru | I26: ZD4B | J26: DC Karawang Lot. 41 | K26: 9 | L26: CBU | N26: AVR20RB226L8
B27: HM Sampoerna PT | C27: FA045796.14 | D27: 76 | E27: Box | F27: 43306 | G27: ZD2D | H27: ADW Pekanbaru | I27: ZD4B | J27: DC Karawang Lot. 41 | K27: 9 | L27: CBU | N27: DSM12RC156L8
B28: HM Sampoerna PT | C28: FA045795.13 | D28: 120 | E28: Box | F28: 43306 | G28: ZD2D | H28: ADW Pekanbaru | I28: ZD4B | J28: DC Karawang Lot. 41 | K28: 9 | L28: CBU | N28: MLD12RB146L8
B29: HM Sampoerna PT | C29: FA044121.19 | D29: 190 | E29: Box | F29: 43306 | G29: ZD2D | H29: ADW Pekanbaru | I29: ZD4B | J29: DC Karawang Lot. 41 | K29: 9 | L29: CBU | N29: MLD16RC204L8
B30: HM Sampoerna PT | C30: FA061184.02 | D30: 177 | E30: Box | F30: 43306 | G30: ZD2D | H30: ADW Pekanbaru | I30: ZD4B | J30: DC Karawang Lot. 41 | K30: 9 | L30: CBU | N30: MFB20RA224L8
B31: HM Sampoerna PT | C31: FA067816.01 | D31: 60 | E31: Box | F31: 43306 | G31: ZD2D | H31: ADW Pekanbaru | I31: ZD4B | J31: DC Karawang Lot. 41 | K31: 9 | L31: CBU | N31: UBL12RA134L8
A32: 4701367451 | B32: HM Sampoerna PT | C32: FA071127.00 | D32: 50 | E32: Box | F32: 43306 | G32: ZD2F | H32: ADW Air Molek | I32: ZD4A | J32: DC Karawang Lot. 17 | K32: 10 | L32: CBU | M32: *Gab Duri + Molek | N32: SAH12RC113L8
A33: 4701367452 | B33: HM Sampoerna PT | C33: FA048259.05 | D33: 18 | E33: Box | F33: 43306 | G33: ZD2F | H33: ADW Air Molek | I33: ZD4B | J33: DC Karawang Lot. 41 | K33: 10 | L33: CBU | M33: *Gab Duri + Molek | N33: AVR20RB226L8
B34: HM Sampoerna PT | C34: FA048258.06 | D34: 1 | E34: Box | F34: 43306 | G34: ZD2F | H34: ADW Air Molek | I34: ZD4B | J34: DC Karawang Lot. 41 | K34: 10 | L34: CBU | M34: *Gab Duri + Molek | N34: AVM20RB226L8
B35: HM Sampoerna PT | C35: FA045795.13 | D35: 24 | E35: Box | F35: 43306 | G35: ZD2F | H35: ADW Air Molek | I35: ZD4B | J35: DC Karawang Lot. 41 | K35: 10 | L35: CBU | M35: *Gab Duri + Molek | N35: MLD12RB146L8
B36: HM Sampoerna PT | C36: FA044121.19 | D36: 135 | E36: Box | F36: 43306 | G36: ZD2F | H36: ADW Air Molek | I36: ZD4B | J36: DC Karawang Lot. 41 | K36: 10 | L36: CBU | M36: *Gab Duri + Molek | N36: MLD16RC204L8
B37: HM Sampoerna PT | C37: FA061184.02 | D37: 10 | E37: Box | F37: 43306 | G37: ZD2F | H37: ADW Air Molek | I37: ZD4B | J37: DC Karawang Lot. 41 | K37: 10 | L37: CBU | M37: *Gab Duri + Molek | N37: MFB20RA224L8
B38: HM Sampoerna PT | C38: FA067816.01 | D38: 20 | E38: Box | F38: 43306 | G38: ZD2F | H38: ADW Air Molek | I38: ZD4B | J38: DC Karawang Lot. 41 | K38: 10 | L38: CBU | M38: *Gab Duri + Molek | N38: UBL12RA134L8
B39: HM Sampoerna PT | C39: FA045300.04 | D39: 30 | E39: Box | F39: 43306 | G39: ZD2F | H39: ADW Air Molek | I39: ZD4B | J39: DC Karawang Lot. 41 | K39: 10 | L39: CBU | M39: *Gab Duri + Molek | N39: DMM16RA179L8
A40: 4701367453 | B40: HM Sampoerna PT | C40: FA035621.15 | D40: 20 | E40: Box | F40: 43306 | G40: ZD2E | H40: ADW Duri | I40: ZD4A | J40: DC Karawang Lot. 17 | K40: 10 | L40: CBU | M40: *Gab Duri + Molek | N40: DSB12RA170L8
B41: HM Sampoerna PT | C41: FA010784.17 | D41: 12 | E41: Box | F41: 43306 | G41: ZD2E | H41: ADW Duri | I41: ZD4A | J41: DC Karawang Lot. 17 | K41: 10 | L41: CBU | M41: *Gab Duri + Molek | N41: DSS16RA202L8
...

Sheet Kamis
A1: ="Pengiriman ( Kamis ) Tgl. "&TEXT(MID(Rabu!A1,FIND(".",Rabu!A1,1)+2,17)+1,"dd mmmm yyyy") -> Pengiriman ( Kamis ) Tgl. 26 July 2018
A3: STO Number | B3: Supplier | C3: Item | D3: Qty | E3: UoM | F3: Promise Date | H3: Ship To | J3: From | K3: Seq | L3: VehicleType | M3: Keterangan | N3: Brand
B4: HM Sampoerna PT | C4: FA035621.15 | D4: 207 | E4: Box | F4: 43307 | G4: ZD1L | H4: Depo Medan | I4: ZD4A | J4: DC Karawang Lot. 17 | K4: 1 | L4: Cont 20FT | N4: DSB12RA170L8
B5: HM Sampoerna PT | C5: FA071115.00 | D5: 155 | E5: Box | F5: 43307 | G5: ZD1L | H5: Depo Medan | I5: ZD4A | J5: DC Karawang Lot. 17 | K5: 1 | L5: Cont 20FT | N5: PNK12RC112L8
B6: HM Sampoerna PT | C6: FA071115.00 | D6: 205 | E6: Box | F6: 43307 | G6: ZD1L | H6: Depo Medan | I6: ZD4A | J6: DC Karawang Lot. 17 | K6: 2 | L6: Cont 40FT HC | N6: PNK12RC112L8
B7: Philip Morris Indonesia PT | C7: FA052576.13 | D7: 182 | E7: Box | F7: 43307 | G7: ZD1L | H7: Depo Medan | I7: ZD4A | J7: DC Karawang Lot. 17 | K7: 2 | L7: Cont 40FT HC | N7: MBR20RC233L8
B8: Philip Morris Indonesia PT | C8: FA068715.04 | D8: 100 | E8: Box | F8: 43307 | G8: ZD1L | H8: Depo Medan | I8: ZD4A | J8: DC Karawang Lot. 17 | K8: 2 | L8: Cont 40FT HC | N8: MBL20RB233L8
B9: HM Sampoerna PT | C9: FA045796.14 | D9: 51 | E9: Box | F9: 43307 | G9: ZD1L | H9: Depo Medan | I9: ZD4B | J9: DC Karawang Lot. 41 | K9: 2 | L9: Cont 40FT HC | N9: DSM12RC156L8
B10: HM Sampoerna PT | C10: FA044121.19 | D10: 300 | E10: Box | F10: 43307 | G10: ZD1L | H10: Depo Medan | I10: ZD4B | J10: DC Karawang Lot. 41 | K10: 2 | L10: Cont 40FT HC | N10: MLD16RC204L8
B11: HM Sampoerna PT | C11: FA045796.14 | D11: 729 | E11: Box | F11: 43307 | G11: ZD1L | H11: Depo Medan | I11: ZD4B | J11: DC Karawang Lot. 41 | K11: 3 | L11: Cont 40FT HC | N11: DSM12RC156L8
B12: HM Sampoerna PT | C12: FA035621.15 | D12: 166 | E12: Box | F12: 43307 | G12: ZD2A | H12: ADW Padang | I12: ZD4A | J12: DC Karawang Lot. 17 | K12: 4 | L12: Cont 40FT HC | N12: DSB12RA170L8
B13: HM Sampoerna PT | C13: FA064382.01 | D13: 160 | E13: Box | F13: 43307 | G13: ZD2A | H13: ADW Padang | I13: ZD4A | J13: DC Karawang Lot. 17 | K13: 4 | L13: Cont 40FT HC | N13: DSS12RA151L8
B14: PT. Sampoerna Indonesia Sembilan | C14: FA068324.02 | D14: 83 | E14: Box | F14: 43307 | G14: ZD2A | H14: ADW Padang | I14: ZD4A | J14: DC Karawang Lot. 17 | K14: 4 | L14: Cont 40FT HC | N14: UML12RB134L8
B15: PT. Sampoerna Indonesia Sembilan | C15: FA067814.02 | D15: 157 | E15: Box | F15: 43307 | G15: ZD2A | H15: ADW Padang | I15: ZD4A | J15: DC Karawang Lot. 17 | K15: 4 | L15: Cont 40FT HC | N15: UML16RB179L8
... B42: HM Sampoerna PT | C42: FA045300.04 | D42: 210 | E42: Box | F42: 43307 | G42: ZD2E | H42: ADW Duri | I42: ZD4B | J42: DC Karawang Lot. 41 | K42: 9 | L42: CBU | N42: DMM16RA179L8
B43: HM Sampoerna PT | C43: FA035621.15 | D43: 28 | E43: Box | F43: 43307 | G43: ZD3O | H43: DPC Tuba | I43: ZD4A | J43: DC Karawang Lot. 17 | K43: 10 | L43: CBU | M43: *Gab Kotabumi + Pringsewu | N43: DSB12RA170L8
B44: HM Sampoerna PT | C44: FA064382.01 | D44: 17 | E44: Box | F44: 43307 | G44: ZD3O | H44: DPC Tuba | I44: ZD4A | J44: DC Karawang Lot. 17 | K44: 10 | L44: CBU | M44: *Gab Kotabumi + Pringsewu | N44: DSS12RA151L8
B45: HM Sampoerna PT | C45: FA010784.17 | D45: 8 | E45: Box | F45: 43307 | G45: ZD3O | H45: DPC Tuba | I45: ZD4A | J45: DC Karawang Lot. 17 | K45: 10 | L45: CBU | M45: *Gab Kotabumi + Pringsewu | N45: DSS16RA202L8
B46: PT. Sampoerna Indonesia Sembilan | C46: FA067814.02 | D46: 2 | E46: Box | F46: 43307 | G46: ZD3O | H46: DPC Tuba | I46: ZD4A | J46: DC Karawang Lot. 17 | K46: 10 | L46: CBU | M46: *Gab Kotabumi + Pringsewu | N46: UML16RB179L8
B47: Philip Morris Indonesia PT | C47: FA052576.13 | D47: 20 | E47: Box | F47: 43307 | G47: ZD3O | H47: DPC Tuba | I47: ZD4A | J47: DC Karawang Lot. 17 | K47: 10 | L47: CBU | M47: *Gab Kotabumi + Pringsewu | N47: MBR20RC233L8
B48: Philip Morris Indonesia PT | C48: FA068715.04 | D48: 5 | E48: Box | F48: 43307 | G48: ZD3O | H48: DPC Tuba | I48: ZD4A | J48: DC Karawang Lot. 17 | K48: 10 | L48: CBU | M48: *Gab Kotabumi + Pringsewu | N48: MBL20RB233L8
B49: HM Sampoerna PT | C49: FA048258.06 | D49: 3 | E49: Box | F49: 43307 | G49: ZD3O | H49: DPC Tuba | I49: ZD4B | J49: DC Karawang Lot. 41 | K49: 10 | L49: CBU | M49: *Gab Kotabumi + Pringsewu | N49: AVM20RB226L8
B50: HM Sampoerna PT | C50: FA044121.19 | D50: 85 | E50: Box | F50: 43307 | G50: ZD3O | H50: DPC Tuba | I50: ZD4B | J50: DC Karawang Lot. 41 | K50: 10 | L50: CBU | M50: *Gab Kotabumi + Pringsewu | N50: MLD16RC204L8
B51: HM Sampoerna PT | C51: FA061184.02 | D51: 43 | E51: Box | F51: 43307 | G51: ZD3O | H51: DPC Tuba | I51: ZD4B | J51: DC Karawang Lot. 41 | K51: 10 | L51: CBU | M51: *Gab Kotabumi + Pringsewu | N51: MFB20RA224L8
B52: HM Sampoerna PT | C52: FA069010.02 | D52: 10 | E52: Box | F52: 43307 | G52: ZD3O | H52: DPC Tuba | I52: ZD4B | J52: DC Karawang Lot. 41 | K52: 10 | L52: CBU | M52: *Gab Kotabumi + Pringsewu | N52: MFB12RA134L8
B53: HM Sampoerna PT | C53: FA045300.04 | D53: 215 | E53: Box | F53: 43307 | G53: ZD3O | H53: DPC Tuba | I53: ZD4B | J53: DC Karawang Lot. 41 | K53: 10 | L53: CBU | M53: *Gab Kotabumi + Pringsewu | N53: DMM16RA179L8
B54: HM Sampoerna PT | C54: FA048259.05 | D54: 99 | E54: Box | F54: 43307 | G54: ZD4C | H54: ADW Jakarta Utara | I54: ZD4B | J54: DC Karawang Lot. 41 | K54: 11 | L54: Standard | N54: AVR20RB226L8
B55: HM Sampoerna PT | C55: FA045796.14 | D55: 130 | E55: Box | F55: 43307 | G55: ZD4C | H55: ADW Jakarta Utara | I55: ZD4B | J55: DC Karawang Lot. 41 | K55: 11 | L55: Standard | N55: DSM12RC156L8
B56: HM Sampoerna PT | C56: FA044121.19 | D56: 70 | E56: Box | F56: 43307 | G56: ZD4C | H56: ADW Jakarta Utara | I56: ZD4B | J56: DC Karawang Lot. 41 | K56: 11 | L56: Standard | N56: MLD16RC204L8
B57: HM Sampoerna PT | C57: FA067816.01 | D57: 9 | E57: Box | F57: 43307 | G57: ZD4C | H57: ADW Jakarta Utara | I57: ZD4B | J57: DC Karawang Lot. 41 | K57: 11 | L57: Standard | N57: UBL12RA134L8
B58: HM Sampoerna PT | C58: FA044121.16 | D58: 165 | E58: Box | F58: 43307 | G58: ZD4C | H58: ADW Jakarta Utara | I58: ZD4B | J58: DC Karawang Lot. 41 | K58: 11 | L58: Standard | N58: MLD16RA195L8
B59: HM Sampoerna PT | C59: FA044121.19 | D59: 775 | E59: Box | F59: 43307 | G59: ZD4C | H59: ADW Jakarta Utara | I59: ZD4B | J59: DC Karawang Lot. 41 | K59: 12 | L59: CBU | N59: MLD16RC204L8
B60: HM Sampoerna PT | C60: FA044121.19 | D60: 500 | E60: Box | F60: 43307 | G60: ZD4H | H60: ADW Jakarta Timur A | I60: ZD4B | J60: DC Karawang Lot. 41 | K60: 13 | L60: Standard | N60: MLD16RC204L8
B61: HM Sampoerna PT | C61: FA069010.02 | D61: 16 | E61: Box | F61: 43307 | G61: ZD4H | H61: ADW Jakarta Timur A | I61: ZD4B | J61: DC Karawang Lot. 41 | K61: 13 | L61: Standard | N61: MFB12RA134L8
B62: HM Sampoerna PT | C62: FA044121.16 | D62: 19 | E62: Box | F62: 43307 | G62: ZD4H | H62: ADW Jakarta Timur A | I62: ZD4B | J62: DC Karawang Lot. 41 | K62: 13 | L62: Standard | N62: MLD16RA195L8
B63: HM Sampoerna PT | C63: FA035621.15 | D63: 100 | E63: Box | F63: 43307 | G63: ZD4F | H63: DPC Jakarta Timur | I63: ZD4A | J63: DC Karawang Lot. 17 | K63: 14 | L63: Standard | N63: DSB12RA170L8
B64: HM Sampoerna PT | C64: FA048259.05 | D64: 55 | E64: Box | F64: 43307 | G64: ZD4F | H64: DPC Jakarta Timur | I64: ZD4B | J64: DC Karawang Lot. 41 | K64: 14 | L64: Standard | N64: AVR20RB226L8
B65: HM Sampoerna PT | C65: FA044121.19 | D65: 20 | E65: Box | F65: 43307 | G65: ZD4F | H65: DPC Jakarta Timur | I65: ZD4B | J65: DC Karawang Lot. 41 | K65: 14 | L65: Standard | N65: MLD16RC204L8
... B103: HM Sampoerna PT | C103: FA044121.19 | D103: 775 | E103: Box | F103: 43307 | G103: ZD5C | H103: ADW Sukabumi | I103: ZD4B | J103: DC Karawang Lot. 41 | K103: 23 | L103: CBU | N103: MLD16RC204L8
B104: HM Sampoerna PT | C104: FA045796.14 | D104: 100 | E104: Box | F104: 43307 | G104: ZD5E | H104: ADW Garut | I104: ZD4B | J104: DC Karawang Lot. 41 | K104: 24 | L104: Standard | M104: *Gab Tasik + Garut | N104: DSM12RC156L8
...

Sheet Jumat
A1: ="Pengiriman ( Jumat ) Tgl. "&TEXT(MID(Kamis!A1,FIND(".",Kamis!A1,1)+2,17)+1,"dd mmmm yyyy") -> Pengiriman ( Jumat ) Tgl. 27 July 2018
A3: STO Number | B3: Supplier | C3: Item | D3: Qty | E3: UoM | F3: Promise Date | H3: Ship To | J3: From | K3: Seq | L3: VehicleType | M3: Keterangan | N3: Brand
B4: HM Sampoerna PT | C4: FA010784.17 | D4: 40 | E4: Box | F4: 43308 | G4: ZD2D | H4: ADW Pekanbaru | I4: ZD4A | J4: DC Karawang Lot. 17 | K4: 1 | L4: Cont 40FT HC | N4: DSS16RA202L8
B5: PT. Sampoerna Indonesia Sembilan | C5: FA068324.02 | D5: 270 | E5: Box | F5: 43308 | G5: ZD2D | H5: ADW Pekanbaru | I5: ZD4A | J5: DC Karawang Lot. 17 | K5: 1 | L5: Cont 40FT HC | N5: UML12RB134L8
B6: PT. Sampoerna Indonesia Sembilan | C6: FA067814.02 | D6: 300 | E6: Box | F6: 43308 | G6: ZD2D | H6: ADW Pekanbaru | I6: ZD4A | J6: DC Karawang Lot. 17 | K6: 1 | L6: Cont 40FT HC | N6: UML16RB179L8
B7: HM Sampoerna PT | C7: FA045795.13 | D7: 374 | E7: Box | F7: 43308 | G7: ZD2D | H7: ADW Pekanbaru | I7: ZD4B | J7: DC Karawang Lot. 41 | K7: 1 | L7: Cont 40FT HC | N7: MLD12RB146L8
B8: HM Sampoerna PT | C8: FA035621.15 | D8: 60 | E8: Box | F8: 43308 | G8: ZD2E | H8: ADW Duri | I8: ZD4A | J8: DC Karawang Lot. 17 | K8: 2 | L8: CBU | N8: DSB12RA170L8
B9: HM Sampoerna PT | C9: FA064382.01 | D9: 6 | E9: Box | F9: 43308 | G9: ZD2E | H9: ADW Duri | I9: ZD4A | J9: DC Karawang Lot. 17 | K9: 2 | L9: CBU | N9: DSS12RA151L8
B10: PT. Sampoerna Indonesia Sembilan | C10: FA068324.02 | D10: 30 | E10: Box | F10: 43308 | G10: ZD2E | H10: ADW Duri | I10: ZD4A | J10: DC Karawang Lot. 17 | K10: 2 | L10: CBU | N10: UML12RB134L8
B11: PT. Sampoerna Indonesia Sembilan | C11: FA067814.02 | D11: 180 | E11: Box | F11: 43308 | G11: ZD2E | H11: ADW Duri | I11: ZD4A | J11: DC Karawang Lot. 17 | K11: 2 | L11: CBU | N11: UML16RB179L8
B12: Philip Morris Indonesia PT | C12: FA052576.13 | D12: 40 | E12: Box | F12: 43308 | G12: ZD2E | H12: ADW Duri | I12: ZD4A | J12: DC Karawang Lot. 17 | K12: 2 | L12: CBU | N12: MBR20RC233L8
B13: Philip Morris Indonesia PT | C13: FA068715.04 | D13: 15 | E13: Box | F13: 43308 | G13: ZD2E | H13: ADW Duri | I13: ZD4A | J13: DC Karawang Lot. 17 | K13: 2 | L13: CBU | N13: MBL20RB233L8
B14: HM Sampoerna PT | C14: FA044121.19 | D14: 300 | E14: Box | F14: 43308 | G14: ZD2E | H14: ADW Duri | I14: ZD4B | J14: DC Karawang Lot. 41 | K14: 2 | L14: CBU | N14: MLD16RC204L8
B15: HM Sampoerna PT | C15: FA061184.02 | D15: 33 | E15: Box | F15: 43308 | G15: ZD2E | H15: ADW Duri | I15: ZD4B | J15: DC Karawang Lot. 41 | K15: 2 | L15: CBU | N15: MFB20RA224L8
... B49: HM Sampoerna PT | C49: FA045300.04 | D49: 150 | E49: Box | F49: 43308 | G49: ZD3Q | H49: ADW Palembang 2 | I49: ZD4B | J49: DC Karawang Lot. 41 | K49: 6 | L49: CBU | N49: DMM16RA179L8
B50: HM Sampoerna PT | C50: FA035621.15 | D50: 22 | E50: Box | F50: 43308 | G50: ZD3E | H50: ADW Lahat | I50: ZD4A | J50: DC Karawang Lot. 17 | K50: 7 | L50: Standard | M50: *Gab Lahat + Baturaja | N50: DSB12RA170L8
B51: HM Sampoerna PT | C51: FA064382.01 | D51: 30 | E51: Box | F51: 43308 | G51: ZD3E | H51: ADW Lahat | I51: ZD4A | J51: DC Karawang Lot. 17 | K51: 7 | L51: Standard | M51: *Gab Lahat + Baturaja | N51: DSS12RA151L8
B52: PT. Sampoerna Indonesia Sembilan | C52: FA068324.02 | D52: 3 | E52: Box | F52: 43308 | G52: ZD3E | H52: ADW Lahat | I52: ZD4A | J52: DC Karawang Lot. 17 | K52: 7 | L52: Standard | M52: *Gab Lahat + Baturaja | N52: UML12RB134L8
B53: PT. Sampoerna Indonesia Sembilan | C53: FA067814.02 | D53: 2 | E53: Box | F53: 43308 | G53: ZD3E | H53: ADW Lahat | I53: ZD4A | J53: DC Karawang Lot. 17 | K53: 7 | L53: Standard | M53: *Gab Lahat + Baturaja | N53: UML16RB179L8
B54: Philip Morris Indonesia PT | C54: FA052576.13 | D54: 20 | E54: Box | F54: 43308 | G54: ZD3E | H54: ADW Lahat | I54: ZD4A | J54: DC Karawang Lot. 17 | K54: 7 | L54: Standard | M54: *Gab Lahat + Baturaja | N54: MBR20RC233L8
B55: Philip Morris Indonesia PT | C55: FA068715.04 | D55: 3 | E55: Box | F55: 43308 | G55: ZD3E | H55: ADW Lahat | I55: ZD4A | J55: DC Karawang Lot. 17 | K55: 7 | L55: Standard | M55: *Gab Lahat + Baturaja | N55: MBL20RB233L8
B56: Philip Morris Indonesia PT | C56: FA069748.02 | D56: 1 | E56: Box | F56: 43308 | G56: ZD3E | H56: ADW Lahat | I56: ZD4A | J56: DC Karawang Lot. 17 | K56: 7 | L56: Standard | M56: *Gab Lahat + Baturaja | N56: MMI20RC233L8
B57: HM Sampoerna PT | C57: FA045795.13 | D57: 48 | E57: Box | F57: 43308 | G57: ZD3E | H57: ADW Lahat | I57: ZD4B | J57: DC Karawang Lot. 41 | K57: 7 | L57: Standard | M57: *Gab Lahat + Baturaja | N57: MLD12RB146L8
B58: HM Sampoerna PT | C58: FA061184.02 | D58: 46 | E58: Box | F58: 43308 | G58: ZD3E | H58: ADW Lahat | I58: ZD4B | J58: DC Karawang Lot. 41 | K58: 7 | L58: Standard | M58: *Gab Lahat + Baturaja | N58: MFB20RA224L8
B59: HM Sampoerna PT | C59: FA067816.01 | D59: 2 | E59: Box | F59: 43308 | G59: ZD3E | H59: ADW Lahat | I59: ZD4B | J59: DC Karawang Lot. 41 | K59: 7 | L59: Standard | M59: *Gab Lahat + Baturaja | N59: UBL12RA134L8
B60: HM Sampoerna PT | C60: FA069010.02 | D60: 2 | E60: Box | F60: 43308 | G60: ZD3E | H60: ADW Lahat | I60: ZD4B | J60: DC Karawang Lot. 41 | K60: 7 | L60: Standard | M60: *Gab Lahat + Baturaja | N60: MFB12RA134L8
B61: HM Sampoerna PT | C61: FA071127.00 | D61: 20 | E61: Box | F61: 43308 | G61: ZD3E | H61: ADW Lahat | I61: ZD4B | J61: DC Karawang Lot. 41 | K61: 7 | L61: Light | N61: SAH12RC113L8
B62: HM Sampoerna PT | C62: FA035621.15 | D62: 95 | E62: Box | F62: 43308 | G62: ZD3G | H62: ADW Jambi | I62: ZD4A | J62: DC Karawang Lot. 17 | K62: 8 | L62: Standard | N62: DSB12RA170L8
B63: HM Sampoerna PT | C63: FA010784.17 | D63: 10 | E63: Box | F63: 43308 | G63: ZD3G | H63: ADW Jambi | I63: ZD4A | J63: DC Karawang Lot. 17 | K63: 8 | L63: Standard | N63: DSS16RA202L8
B64: HM Sampoerna PT | C64: FA071127.00 | D64: 35 | E64: Box | F64: 43308 | G64: ZD3G | H64: ADW Jambi | I64: ZD4A | J64: DC Karawang Lot. 17 | K64: 8 | L64: Standard | N64: SAH12RC113L8
B65: Philip Morris Indonesia PT | C65: FA068715.04 | D65: 10 | E65: Box | F65: 43308 | G65: ZD3G | H65: ADW Jambi | I65: ZD4A | J65: DC Karawang Lot. 17 | K65: 8 | L65: Standard | N65: MBL20RB233L8
B66: Philip Morris Indonesia PT | C66: FA069748.02 | D66: 2 | E66: Box | F66: 43308 | G66: ZD3G | H66: ADW Jambi | I66: ZD4A | J66: DC Karawang Lot. 17 | K66: 8 | L66: Standard | N66: MMI20RC233L8
B67: HM Sampoerna PT | C67: FA048258.06 | D67: 6 | E67: Box | F67: 43308 | G67: ZD3G | H67: ADW Jambi | I67: ZD4B | J67: DC Karawang Lot. 41 | K67: 8 | L67: Standard | N67: AVM20RB226L8
B68: HM Sampoerna PT | C68: FA044121.19 | D68: 25 | E68: Box | F68: 43308 | G68: ZD3G | H68: ADW Jambi | I68: ZD4B | J68: DC Karawang Lot. 41 | K68: 8 | L68: Standard | N68: MLD16RC204L8
B69: HM Sampoerna PT | C69: FA062333.03 | D69: 36 | E69: Box | F69: 43308 | G69: ZD3G | H69: ADW Jambi | I69: ZD4B | J69: DC Karawang Lot. 41 | K69: 8 | L69: Standard | N69: MTB16RA200L8
B70: HM Sampoerna PT | C70: FA061184.02 | D70: 81 | E70: Box | F70: 43308 | G70: ZD3G | H70: ADW Jambi | I70: ZD4B | J70: DC Karawang Lot. 41 | K70: 8 | L70: Standard | N70: MFB20RA224L8
B71: HM Sampoerna PT | C71: FA070776.00 | D71: 91 | E71: Box | F71: 43308 | G71: ZD3G | H71: ADW Jambi | I71: ZD4B | J71: DC Karawang Lot. 41 | K71: 8 | L71: Standard | N71: UBL12SA134L8
B72: HM Sampoerna PT | C72: FA064382.01 | D72: 60 | E72: Box | F72: 43308 | G72: ZD3H | H72: ADW Muara Bungo | I72: ZD4A | J72: DC Karawang Lot. 17 | K72: 9 | L72: CBU | N72: DSS12RA151L8
... B87: HM Sampoerna PT | C87: FA061184.02 | D87: 60 | E87: Box | F87: 43308 | G87: ZD3B | H87: ADW Lampung | I87: ZD4B | J87: DC Karawang Lot. 41 | K87: 10 | L87: CBU | N87: MFB20RA224L8
B88: HM Sampoerna PT | C88: FA035621.15 | D88: 35 | E88: Box | F88: 43308 | G88: ZD3N | H88: DPC Kalianda | I88: ZD4A | J88: DC Karawang Lot. 17 | K88: 11 | L88: CBU | M88: *Gab Kalianda + Pringsewu | N88: DSB12RA170L8
...

Sheet Sabtu
A1: ="Pengiriman ( Sabtu ) Tgl. "&TEXT(MID(Jumat!A1,FIND(".",Jumat!A1,1)+2,17)+1,"dd mmmm yyyy") -> Pengiriman ( Sabtu ) Tgl. 28 July 2018
A3: STO Number | B3: Supplier | C3: Item | D3: Qty | E3: UoM | F3: Promise Date | H3: Ship To | J3: From | K3: Seq | L3: VehicleType | M3: Keterangan | N3: Brand
B4: HM Sampoerna PT | C4: FA045795.13 | D4: 60 | E4: Box | F4: 43309 | G4: ZD2A | H4: ADW Padang | I4: ZD4B | J4: DC Karawang Lot. 41 | K4: 1 | L4: Cont 40FT HC | N4: MLD12RB146L8
B5: HM Sampoerna PT | C5: FA045300.04 | D5: 1064 | E5: Box | F5: 43309 | G5: ZD2A | H5: ADW Padang | I5: ZD4B | J5: DC Karawang Lot. 41 | K5: 1 | L5: Cont 40FT HC | N5: DMM16RA179L8
B6: HM Sampoerna PT | C6: FA064382.01 | D6: 15 | E6: Box | F6: 43309 | G6: ZD2A | H6: ADW Padang | I6: ZD4A | J6: DC Karawang Lot. 17 | K6: 2 | L6: Cont 40FT HC | N6: DSS12RA151L8
B7: PT. Sampoerna Indonesia Sembilan | C7: FA068324.02 | D7: 287 | E7: Box | F7: 43309 | G7: ZD2A | H7: ADW Padang | I7: ZD4A | J7: DC Karawang Lot. 17 | K7: 2 | L7: Cont 40FT HC | N7: UML12RB134L8
B8: PT. Sampoerna Indonesia Sembilan | C8: FA067814.02 | D8: 112 | E8: Box | F8: 43309 | G8: ZD2A | H8: ADW Padang | I8: ZD4A | J8: DC Karawang Lot. 17 | K8: 2 | L8: Cont 40FT HC | N8: UML16RB179L8
B9: HM Sampoerna PT | C9: FA045795.13 | D9: 125 | E9: Box | F9: 43309 | G9: ZD2A | H9: ADW Padang | I9: ZD4B | J9: DC Karawang Lot. 41 | K9: 2 | L9: Cont 40FT HC | N9: MLD12RB146L8
B10: HM Sampoerna PT | C10: FA044121.19 | D10: 450 | E10: Box | F10: 43309 | G10: ZD2A | H10: ADW Padang | I10: ZD4B | J10: DC Karawang Lot. 41 | K10: 2 | L10: Cont 40FT HC | N10: MLD16RC204L8
B11: HM Sampoerna PT | C11: FA035621.15 | D11: 59 | E11: Box | F11: 43309 | G11: ZD2E | H11: ADW Duri | I11: ZD4A | J11: DC Karawang Lot. 17 | K11: 3 | L11: CBU | N11: DSB12RA170L8
B12: PT. Sampoerna Indonesia Sembilan | C12: FA068324.02 | D12: 40 | E12: Box | F12: 43309 | G12: ZD2E | H12: ADW Duri | I12: ZD4A | J12: DC Karawang Lot. 17 | K12: 3 | L12: CBU | N12: UML12RB134L8
B13: PT. Sampoerna Indonesia Sembilan | C13: FA067814.02 | D13: 58 | E13: Box | F13: 43309 | G13: ZD2E | H13: ADW Duri | I13: ZD4A | J13: DC Karawang Lot. 17 | K13: 3 | L13: CBU | N13: UML16RB179L8
B14: HM Sampoerna PT | C14: FA045795.13 | D14: 56 | E14: Box | F14: 43309 | G14: ZD2E | H14: ADW Duri | I14: ZD4B | J14: DC Karawang Lot. 41 | K14: 3 | L14: CBU | N14: MLD12RB146L8
B15: HM Sampoerna PT | C15: FA044121.19 | D15: 185 | E15: Box | F15: 43309 | G15: ZD2E | H15: ADW Duri | I15: ZD4B | J15: DC Karawang Lot. 41 | K15: 3 | L15: CBU | N15: MLD16RC204L8
... B40: HM Sampoerna PT | C40: FA045300.04 | D40: 440 | E40: Box | F40: 43309 | G40: ZD3E | H40: ADW Lahat | I40: ZD4B | J40: DC Karawang Lot. 41 | K40: 7 | L40: Standard | N40: DMM16RA179L8
B41: PT. Sampoerna Indonesia Sembilan | C41: FA068324.02 | D41: 22 | E41: Box | F41: 43309 | G41: ZD3G | H41: ADW Jambi | I41: ZD4A | J41: DC Karawang Lot. 17 | K41: 8 | L41: Standard | M41: *Gab Jambi + Muarabungo | N41: UML12RB134L8
B42: HM Sampoerna PT | C42: FA045795.13 | D42: 102 | E42: Box | F42: 43309 | G42: ZD3G | H42: ADW Jambi | I42: ZD4B | J42: DC Karawang Lot. 41 | K42: 8 | L42: Standard | M42: *Gab Jambi + Muarabungo | N42: MLD12RB146L8
B43: HM Sampoerna PT | C43: FA044121.19 | D43: 180 | E43: Box | F43: 43309 | G43: ZD3G | H43: ADW Jambi | I43: ZD4B | J43: DC Karawang Lot. 41 | K43: 8 | L43: Standard | M43: *Gab Jambi + Muarabungo | N43: MLD16RC204L8
B44: HM Sampoerna PT | C44: FA061184.02 | D44: 20 | E44: Box | F44: 43309 | G44: ZD3G | H44: ADW Jambi | I44: ZD4B | J44: DC Karawang Lot. 41 | K44: 8 | L44: Standard | M44: *Gab Jambi + Muarabungo | N44: MFB20RA224L8
B45: PT. Sampoerna Indonesia Sembilan | C45: FA068324.02 | D45: 80 | E45: Box | F45: 43309 | G45: ZD3H | H45: ADW Muara Bungo | I45: ZD4A | J45: DC Karawang Lot. 17 | K45: 8 | L45: Standard | M45: *Gab Jambi + Muarabungo | N45: UML12RB134L8
B46: HM Sampoerna PT | C46: FA045795.13 | D46: 58 | E46: Box | F46: 43309 | G46: ZD3H | H46: ADW Muara Bungo | I46: ZD4B | J46: DC Karawang Lot. 41 | K46: 8 | L46: Standard | M46: *Gab Jambi + Muarabungo | N46: MLD12RB146L8
B47: HM Sampoerna PT | C47: FA044121.19 | D47: 30 | E47: Box | F47: 43309 | G47: ZD3H | H47: ADW Muara Bungo | I47: ZD4B | J47: DC Karawang Lot. 41 | K47: 8 | L47: Standard | M47: *Gab Jambi + Muarabungo | N47: MLD16RC204L8
B48: HM Sampoerna PT | C48: FA035621.15 | D48: 40 | E48: Box | F48: 43309 | G48: ZD3B | H48: ADW Lampung | I48: ZD4A | J48: DC Karawang Lot. 17 | K48: 9 | L48: CBU | N48: DSB12RA170L8
B49: HM Sampoerna PT | C49: FA064382.01 | D49: 110 | E49: Box | F49: 43309 | G49: ZD3B | H49: ADW Lampung | I49: ZD4A | J49: DC Karawang Lot. 17 | K49: 9 | L49: CBU | N49: DSS12RA151L8
B50: Philip Morris Indonesia PT | C50: FA052576.13 | D50: 15 | E50: Box | F50: 43309 | G50: ZD3B | H50: ADW Lampung | I50: ZD4A | J50: DC Karawang Lot. 17 | K50: 9 | L50: CBU | N50: MBR20RC233L8
B51: HM Sampoerna PT | C51: FA045795.13 | D51: 72 | E51: Box | F51: 43309 | G51: ZD3B | H51: ADW Lampung | I51: ZD4B | J51: DC Karawang Lot. 41 | K51: 9 | L51: CBU | N51: MLD12RB146L8
B52: HM Sampoerna PT | C52: FA044121.19 | D52: 160 | E52: Box | F52: 43309 | G52: ZD3B | H52: ADW Lampung | I52: ZD4B | J52: DC Karawang Lot. 41 | K52: 9 | L52: CBU | N52: MLD16RC204L8
B53: HM Sampoerna PT | C53: FA062333.03 | D53: 19 | E53: Box | F53: 43309 | G53: ZD3B | H53: ADW Lampung | I53: ZD4B | J53: DC Karawang Lot. 41 | K53: 9 | L53: CBU | N53: MTB16RA200L8
B54: HM Sampoerna PT | C54: FA061184.02 | D54: 38 | E54: Box | F54: 43309 | G54: ZD3B | H54: ADW Lampung | I54: ZD4B | J54: DC Karawang Lot. 41 | K54: 9 | L54: CBU | N54: MFB20RA224L8
B55: HM Sampoerna PT | C55: FA045300.04 | D55: 198 | E55: Box | F55: 43309 | G55: ZD3B | H55: ADW Lampung | I55: ZD4B | J55: DC Karawang Lot. 41 | K55: 9 | L55: CBU | N55: DMM16RA179L8
B56: HM Sampoerna PT | C56: FA035621.15 | D56: 33 | E56: Box | F56: 43309 | G56: ZD3L | H56: ADW Metro | I56: ZD4A | J56: DC Karawang Lot. 17 | K56: 10 | L56: Standard | N56: DSB12RA170L8
B57: HM Sampoerna PT | C57: FA064382.01 | D57: 67 | E57: Box | F57: 43309 | G57: ZD3L | H57: ADW Metro | I57: ZD4A | J57: DC Karawang Lot. 17 | K57: 10 | L57: Standard | N57: DSS12RA151L8
B58: Philip Morris Indonesia PT | C58: FA052576.13 | D58: 39 | E58: Box | F58: 43309 | G58: ZD3L | H58: ADW Metro | I58: ZD4A | J58: DC Karawang Lot. 17 | K58: 10 | L58: Standard | N58: MBR20RC233L8
B59: HM Sampoerna PT | C59: FA045795.13 | D59: 25 | E59: Box | F59: 43309 | G59: ZD3L | H59: ADW Metro | I59: ZD4B | J59: DC Karawang Lot. 41 | K59: 10 | L59: Standard | N59: MLD12RB146L8
... B135: HM Sampoerna PT | C135: FA044121.19 | D135: 384 | E135: Box | F135: 43309 | G135: ZD5C | H135: ADW Sukabumi | I135: ZD4B | J135: DC Karawang Lot. 41 | K135: 26 | L135: CBU | N135: MLD16RC204L8
B136: HM Sampoerna PT | C136: FA044121.19 | D136: 210 | E136: Box | F136: 43309 | G136: ZD6G | H136: ADW Magelang | I136: ZD4B | J136: DC Karawang Lot. 41 | K136: 27 | L136: Standard | M136: *Gab Yogya + Magelang | N136: MLD16RC204L8
B137: HM Sampoerna PT | C137: FA044121.19 | D137: 330 | E137: Box | F137: 43309 | G137: ZD6F | H137: ADW Yogyakarta | I137: ZD4B | J137: DC Karawang Lot. 41 | K137: 27 | L137: Standard | M137: *Gab Yogya + Magelang | N137: MLD16RC204L8
B138: Philip Morris Indonesia PT | C138: FA052576.13 | D138: 110 | E138: Box | F138: 43309 | G138: ZD6J | H138: ADW Salatiga | I138: ZD4A | J138: DC Karawang Lot. 17 | K138: 28 | L138: CBU | M138: *Gab Surakarta + Salatiga | N138: MBR20RC233L8
B139: Philip Morris Indonesia PT | C139: FA068715.04 | D139: 5 | E139: Box | F139: 43309 | G139: ZD6J | H139: ADW Salatiga | I139: ZD4A | J139: DC Karawang Lot. 17 | K139: 28 | L139: CBU | M139: *Gab Surakarta + Salatiga | N139: MBL20RB233L8
B140: HM Sampoerna PT | C140: FA048259.05 | D140: 8 | E140: Box | F140: 43309 | G140: ZD6J | H140: ADW Salatiga | I140: ZD4B | J140: DC Karawang Lot. 41 | K140: 28 | L140: CBU | M140: *Gab Surakarta + Salatiga | N140: AVR20RB226L8
...

Sheet Minggu
A1: ="Pengiriman ( Minggu ) Tgl. "&TEXT(MID(Sabtu!A1,FIND(".",Sabtu!A1,1)+2,17)+1,"dd mmmm yyyy") -> Pengiriman ( Minggu ) Tgl. 29 July 2018
A3: STO Number | B3: Supplier | C3: Item | D3: Qty | E3: UoM | F3: Promise Date | H3: Ship To | J3: From | K3: Seq | L3: VehicleType | M3: Keterangan | N3: Brand
B4: HM Sampoerna PT | C4: FA045795.13 | D4: 152 | E4: Box | F4: 43310 | G4: ZD3D | H4: ADW Palembang | I4: ZD4B | J4: DC Karawang Lot. 41 | K4: 1 | L4: CBU | N4: MLD12RB146L8
B5: HM Sampoerna PT | C5: FA044121.19 | D5: 230 | E5: Box | F5: 43310 | G5: ZD3D | H5: ADW Palembang | I5: ZD4B | J5: DC Karawang Lot. 41 | K5: 1 | L5: CBU | N5: MLD16RC204L8
B6: HM Sampoerna PT | C6: FA061184.02 | D6: 4 | E6: Box | F6: 43310 | G6: ZD3D | H6: ADW Palembang | I6: ZD4B | J6: DC Karawang Lot. 41 | K6: 1 | L6: CBU | N6: MFB20RA224L8
B7: HM Sampoerna PT | C7: FA045300.04 | D7: 370 | E7: Box | F7: 43310 | G7: ZD3D | H7: ADW Palembang | I7: ZD4B | J7: DC Karawang Lot. 41 | K7: 1 | L7: CBU | N7: DMM16RA179L8
B8: HM Sampoerna PT | C8: FA044121.19 | D8: 540 | E8: Box | F8: 43310 | G8: ZD4C | H8: ADW Jakarta Utara | I8: ZD4B | J8: DC Karawang Lot. 41 | K8: 2 | L8: Standard | N8: MLD16RC204L8
B9: HM Sampoerna PT | C9: FA044121.19 | D9: 540 | E9: Box | F9: 43310 | G9: ZD4C | H9: ADW Jakarta Utara | I9: ZD4B | J9: DC Karawang Lot. 41 | K9: 3 | L9: Standard | N9: MLD16RC204L8
B10: HM Sampoerna PT | C10: FA044121.19 | D10: 540 | E10: Box | F10: 43310 | G10: ZD4H | H10: ADW Jakarta Timur A | I10: ZD4B | J10: DC Karawang Lot. 41 | K10: 4 | L10: Standard | N10: MLD16RC204L8
B11: HM Sampoerna PT | C11: FA044121.19 | D11: 480 | E11: Box | F11: 43310 | G11: ZD4F | H11: DPC Jakarta Timur | I11: ZD4B | J11: DC Karawang Lot. 41 | K11: 5 | L11: Standard | N11: MLD16RC204L8
B12: HM Sampoerna PT | C12: FA069010.02 | D12: 40 | E12: Box | F12: 43310 | G12: ZD4F | H12: DPC Jakarta Timur | I12: ZD4B | J12: DC Karawang Lot. 41 | K12: 5 | L12: Standard | N12: MFB12RA134L8
B13: HM Sampoerna PT | C13: FA048259.05 | D13: 10 | E13: Box | F13: 43310 | G13: ZD4G | H13: ADW Bogor | I13: ZD4B | J13: DC Karawang Lot. 41 | K13: 6 | L13: Standard | N13: AVR20RB226L8
B14: HM Sampoerna PT | C14: FA045796.14 | D14: 201 | E14: Box | F14: 43310 | G14: ZD4G | H14: ADW Bogor | I14: ZD4B | J14: DC Karawang Lot. 41 | K14: 6 | L14: Standard | N14: DSM12RC156L8
B15: HM Sampoerna PT | C15: FA044121.19 | D15: 90 | E15: Box | F15: 43310 | G15: ZD4G | H15: ADW Bogor | I15: ZD4B | J15: DC Karawang Lot. 41 | K15: 6 | L15: Standard | N15: MLD16RC204L8
... B41: HM Sampoerna PT | C41: FA044121.19 | D41: 390 | E41: Box | F41: 43310 | G41: ZD5D | H41: ADW Tasikmalaya | I41: ZD4B | J41: DC Karawang Lot. 41 | K41: 16 | L41: CBU | N41: MLD16RC204L8
